<?xml version="1.0"?>
<robot xmlns:xacro="http://www.ros.org/wiki/xacro" name="robot_scara">

    <!-- Properties-->
    <xacro:property name="size_box_1" value="0.2 0.2 1.8"/>
	<xacro:property name="size_box_2" value="1.8 0.2 0.2"/>
	<xacro:property name="size_box_3" value="1.8 0.2 0.2"/>
    <xacro:property name="size_box_4" value="0.2 0.2 1.2"/>

    <!--World-->
    <xacro:macro name="base_link" params="">

        <gazebo>
            <plugin name="gazebo_ros_control" filename="libgazebo_ros_control.so">
                <robotNamespace>/robot_scara</robotNamespace>
            </plugin>
        </gazebo>

        <link name="world">
        </link>

        <link name="primer_link">
            <inertial>
                <origin xyz="0 0 0" rpy="0 0 0"/>
                <mass value="0.5" />
                <inertia ixx="1.0" ixy="0.0" ixz="0.0" iyy="1.0" iyz="0.0" izz="1.0"/>
            </inertial>
            <collision>
                <origin xyz="0 0 0" rpy="0 0 0"/>
                <geometry>
                    <box size = "${size_box_1}"/>
                </geometry>
            </collision>
            <visual>
                <origin xyz="0 0 0" rpy="0.0 0 0"/>
                <geometry>
                    <box size = "${size_box_1}"/>
                </geometry>
            </visual>
        </link>

        <gazebo reference="primer_link">
            <kp>100000.0</kp>
            <kd>100000.0</kd>
            <mu1>10.0</mu1>
            <mu2>10.0</mu2>
        </gazebo>

        <joint name="base_joint" type="fixed">
            <parent link="world"/>
            <child link="primer_link"/>
            <origin xyz="0.0 0 0.9" rpy="0 0 0"/>
        </joint>
   
        <link name="segundo_link">
            <inertial>
                <origin xyz="0.8 0 0.0" rpy="0 0 0"/>
                <mass value="0.2" />
                <inertia ixx="1.0" ixy="0.0" ixz="0.0" iyy="1.0" iyz="0.0" izz="1.0"/>
            </inertial>
            <collision>
                <origin xyz="0.8 0.0 0.0" rpy="0 0 0"/>
                <geometry>
                    <box size = "${size_box_2}"/>
                </geometry>
            </collision>
            <visual>
                <origin xyz="0.8 0.0 0.0" rpy="0.0 0 0"/>
                <geometry>
                    <box size = "${size_box_2}"/>
                </geometry>
            </visual>
        </link>

        <gazebo reference="segundo_link">
            <kp>100000.0</kp>
            <kd>100000.0</kd>
            <mu1>10.0</mu1>
            <mu2>10.0</mu2>
        </gazebo>

        <joint name="segundo_joint" type="revolute">
            <parent link="primer_link"/>
            <child link="segundo_link"/>
            <origin xyz="0.0 0.0 1.0" rpy="0 0 0"/>
            <limit lower="-1.57" upper="1.57" effort="0.1" velocity="0.3"/>
            <axis xyz="0 0 1"/>
        </joint>
    
        <transmission name="trans1">
            <type>transmission_interface/SimpleTransmission</type>
            <joint name="segundo_joint">
                <hardwareInterface>hardware_interface/EffortJointInterface</hardwareInterface>
            </joint>
            <actuator name="motor1">
                <hardwareInterface>hardware_interface/EffortJointInterface</hardwareInterface>
                <mechanicalReduction>1</mechanicalReduction>
            </actuator>
        </transmission>

        <link name="tercer_link">
            <inertial>
                <origin xyz="0.8 0 0.0" rpy="0 0 0"/>
                <mass value="0.2" />
                <inertia ixx="1.0" ixy="0.0" ixz="0.0" iyy="1.0" iyz="0.0" izz="1.0"/>
            </inertial>
            <collision>
                <origin xyz="0.8 0 0.0" rpy="0 0 0"/>
                <geometry>
                    <box size = "${size_box_3}"/>
                </geometry>
            </collision>
            <visual>
                <origin xyz="0.8 0 0.0" rpy="0.0 0 0"/>
                <geometry>
                    <box size = "${size_box_3}"/>
                </geometry>
            </visual>
        </link>

        <gazebo reference="tercer_link">
            <kp>100000.0</kp>
            <kd>100000.0</kd>
            <mu1>10.0</mu1>
            <mu2>10.0</mu2>
        </gazebo>

        <joint name="tercer_joint" type="revolute">
            <parent link="segundo_link"/>
            <child link="tercer_link"/>
            <origin xyz="1.6 0 0.2      " rpy="0 0 0"/>
            <limit lower="-1.57" upper="1.57" effort="0.1" velocity="0.3"/>
            <axis xyz="0 0 1"/>
        </joint>
    
        <transmission name="trans2">
            <type>transmission_interface/SimpleTransmission</type>
            <joint name="tercer_joint">
                <hardwareInterface>hardware_interface/EffortJointInterface</hardwareInterface>
            </joint>
            <actuator name="motor2">
                <hardwareInterface>hardware_interface/EffortJointInterface</hardwareInterface>
                <mechanicalReduction>1</mechanicalReduction>
            </actuator>
        </transmission>

        <link name="cuarto_link">
            <inertial>
                <origin xyz="1.8 0 0.0" rpy="0 0 0"/>
                <mass value="0.01" />
                <inertia ixx="1.0" ixy="0.0" ixz="0.0" iyy="1.0" iyz="0.0" izz="1.0"/>
            </inertial>
            <collision>
                <origin xyz="1.8 0 0.0" rpy="0 0 0"/>
                <geometry>
                    <box size = "${size_box_4}"/>
                </geometry>
            </collision>
            <visual>
                <origin xyz="1.8 0 0.0" rpy="0.0 0 0"/>
                <geometry>
                    <box size = "${size_box_4}"/>
                </geometry>
            </visual>
        </link>

        <gazebo reference="cuarto_link">
            <kp>100000.0</kp>
            <kd>100000.0</kd>
            <mu1>10.0</mu1>
            <mu2>10.0</mu2>
        </gazebo>

        <joint name="cuarto_joint" type="prismatic">
            <parent link="tercer_link"/>
            <child link="cuarto_link"/>
            <origin xyz="0.0 0 0.0" rpy="0 0 0"/>
            <limit lower="-0.5" upper="0.50" effort="0.1" velocity="0.3"/>
            <axis xyz="0 0 1"/>
        </joint>
        <transmission name="trans3">
            <type>transmission_interface/SimpleTransmission</type>
            <joint name="cuarto_joint">
                <hardwareInterface>hardware_interface/PositionJointInterface</hardwareInterface>
            </joint>
            <actuator name="motor3">
                <hardwareInterface>hardware_interface/PositionJointInterface</hardwareInterface>
                <mechanicalReduction>1</mechanicalReduction>
            </actuator>
        </transmission>

        <joint name="camera_joint" type="fixed">
            <axis xyz="0 1 0" />
            <origin xyz="1.95 0 -0.55" rpy="0 1.57 0"/>
            <parent link="cuarto_link"/>
            <child link="camera_link"/>
        </joint>

      
        <link name="camera_link">
            <collision>
                <origin xyz="0 0 0" rpy="0 0 0"/>
                <geometry>
	                <box size="0.1 0.1 0.1"/>
                </geometry>
            </collision>

            <visual>
                <origin xyz="0 0 0" rpy="0 0 0"/>
                <geometry>
	                <box size="0.1 0.1 0.1"/>
                </geometry>
            </visual>

            <inertial>
                <mass value="1e-5" />
                <origin xyz="0 0 0" rpy="0 0 0"/>
                <inertia ixx="1e-6" ixy="0" ixz="0" iyy="1e-6" iyz="0" izz="1e-6" />
            </inertial>
        </link>

        <joint name="camera_optical_joint" type="fixed">
            <origin xyz="0 0 0" rpy="-1.57 0.0 -1.57"/>
            <parent link="camera_link"/>
            <child link="camera_link_optical"/>
        </joint>

        <link name="camera_link_optical">
        </link>
        <gazebo reference="camera_link">
            <sensor type="camera" name="camera1">
                <update_rate>30.0</update_rate>
                <camera name="camera_scara">
                    <horizontal_fov>1.3962634</horizontal_fov>
                    <image>
                        <width>800</width>
                        <height>800</height>
                        <format>R8G8B8</format>
                    </image>
                    <clip>
                        <near>0.02</near>
                        <far>300</far>
                    </clip>
                    <noise>
                        <type>gaussian</type>
                        <mean>0.0</mean>
                        <stddev>0.007</stddev>
                    </noise>
                </camera>
                <plugin name="camera_controller" filename="libgazebo_ros_camera.so">
                    <alwaysOn>true</alwaysOn>
                    <updateRate>0.0</updateRate>
                    <cameraName>robot_scara/camera1</cameraName>
                    <imageTopicName>image_scara</imageTopicName>
                    <cameraInfoTopicName>camera_info</cameraInfoTopicName>
                    <frameName>camera_link_optical</frameName>
                    <hackBaseline>0.0</hackBaseline>
                    <distortionK1>0.0</distortionK1>
                    <distortionK2>0.0</distortionK2>
                    <distortionK3>0.0</distortionK3>
                    <distortionT1>0.0</distortionT1>
                    <distortionT2>0.0</distortionT2>
                    <CxPrime>0</CxPrime>
                    <Cx>0.0</Cx>
                    <Cy>0.0</Cy>
                    <focalLength>0.0</focalLength>
                </plugin>
            </sensor>
        </gazebo>

    </xacro:macro>

    <xacro:base_link />

</robot>